{"uuid": "fc3b4f15-2319-4dfe-b387-6d476d89043c", "children": ["81a2cfa6-caa3-4479-92c8-18f3fa9a61c0"], "befores": [{"name": "back_login_page", "status": "broken", "statusDetails": {"message": "urllib3.exceptions.MaxRetryError: HTTPConnectionPool(host='localhost', port=52526): Max retries exceeded with url: /session/c2cf0860457743166cba77120e98e581/url (Caused by NewConnectionError('<urllib3.connection.HTTPConnection object at 0x00D3FC50>: Failed to establish a new connection: [WinError 10061] 由于目标计算机积极拒绝，无法连接。'))\n", "trace": "  File \"C:\\Users\\15572\\Desktop\\test\\.virtualenv\\nm_web-eiUOuFSS\\lib\\site-packages\\pluggy\\_callers.py\", line 39, in _multicall\n    res = hook_impl.function(*args)\n  File \"C:\\Users\\15572\\Desktop\\test\\.virtualenv\\nm_web-eiUOuFSS\\lib\\site-packages\\_pytest\\fixtures.py\", line 1111, in pytest_fixture_setup\n    result = call_fixture_func(fixturefunc, request, kwargs)\n  File \"C:\\Users\\15572\\Desktop\\test\\.virtualenv\\nm_web-eiUOuFSS\\lib\\site-packages\\_pytest\\fixtures.py\", line 883, in call_fixture_func\n    fixture_result = next(generator)\n  File \"C:\\Users\\15572\\Desktop\\test\\nm_web\\project\\test_case\\conftest.py\", line 23, in back_login_page\n    init_fixture.get('https://www.azazie.com/user/login')\n  File \"C:\\Users\\15572\\Desktop\\test\\.virtualenv\\nm_web-eiUOuFSS\\lib\\site-packages\\selenium\\webdriver\\remote\\webdriver.py\", line 442, in get\n    self.execute(Command.GET, {'url': url})\n  File \"C:\\Users\\15572\\Desktop\\test\\.virtualenv\\nm_web-eiUOuFSS\\lib\\site-packages\\selenium\\webdriver\\remote\\webdriver.py\", line 428, in execute\n    response = self.command_executor.execute(driver_command, params)\n  File \"C:\\Users\\15572\\Desktop\\test\\.virtualenv\\nm_web-eiUOuFSS\\lib\\site-packages\\selenium\\webdriver\\remote\\remote_connection.py\", line 347, in execute\n    return self._request(command_info[0], url, body=data)\n  File \"C:\\Users\\15572\\Desktop\\test\\.virtualenv\\nm_web-eiUOuFSS\\lib\\site-packages\\selenium\\webdriver\\remote\\remote_connection.py\", line 369, in _request\n    response = self._conn.request(method, url, body=body, headers=headers)\n  File \"C:\\Users\\15572\\Desktop\\test\\.virtualenv\\nm_web-eiUOuFSS\\lib\\site-packages\\urllib3\\request.py\", line 79, in request\n    method, url, fields=fields, headers=headers, **urlopen_kw\n  File \"C:\\Users\\15572\\Desktop\\test\\.virtualenv\\nm_web-eiUOuFSS\\lib\\site-packages\\urllib3\\request.py\", line 170, in request_encode_body\n    return self.urlopen(method, url, **extra_kw)\n  File \"C:\\Users\\15572\\Desktop\\test\\.virtualenv\\nm_web-eiUOuFSS\\lib\\site-packages\\urllib3\\poolmanager.py\", line 376, in urlopen\n    response = conn.urlopen(method, u.request_uri, **kw)\n  File \"C:\\Users\\15572\\Desktop\\test\\.virtualenv\\nm_web-eiUOuFSS\\lib\\site-packages\\urllib3\\connectionpool.py\", line 826, in urlopen\n    **response_kw\n  File \"C:\\Users\\15572\\Desktop\\test\\.virtualenv\\nm_web-eiUOuFSS\\lib\\site-packages\\urllib3\\connectionpool.py\", line 826, in urlopen\n    **response_kw\n  File \"C:\\Users\\15572\\Desktop\\test\\.virtualenv\\nm_web-eiUOuFSS\\lib\\site-packages\\urllib3\\connectionpool.py\", line 826, in urlopen\n    **response_kw\n  File \"C:\\Users\\15572\\Desktop\\test\\.virtualenv\\nm_web-eiUOuFSS\\lib\\site-packages\\urllib3\\connectionpool.py\", line 786, in urlopen\n    method, url, error=e, _pool=self, _stacktrace=sys.exc_info()[2]\n  File \"C:\\Users\\15572\\Desktop\\test\\.virtualenv\\nm_web-eiUOuFSS\\lib\\site-packages\\urllib3\\util\\retry.py\", line 592, in increment\n    raise MaxRetryError(_pool, url, error or ResponseError(cause))\n"}, "start": 1652356849722, "stop": 1652356865987}], "start": 1652356849722, "stop": 1652356866188}